<?xml version="1.0"?>
<robot xmlns:xacro="http://ros.org/wiki/xacro" name="diff_bot">

    <!-- Parameters -->
    <xacro:property name="wheel_radius" value="0.15"/>
    <xacro:property name="wheel_width" value="0.05"/>
    <xacro:property name="wheel_separation" value="0.4"/>
    <xacro:property name="base_size_x" value="0.4"/>
    <xacro:property name="base_size_y" value="0.3"/>
    <xacro:property name="base_size_z" value="0.2"/>
    <xacro:property name="caster_radius" value="0.05"/>

    <!-- Dummy link -->
    <link name="dummy_link"></link>

    <joint name="dummy_joint" type="fixed">
        <parent link="dummy_link"/>
        <child link="base_link"/>
        <origin xyz="0 0 0" rpy="0 0 0"/>
    </joint>

    <!-- Base Link -->
    <link name="base_link">
        <inertial>
            <mass value="5.0"/>
            <inertia ixx="0.1" ixy="0" ixz="0" iyy="0.1" iyz="0" izz="0.1"/>
        </inertial>
        <visual name="base_visual">
            <geometry>
                <box size="${base_size_x} ${base_size_y} ${base_size_z}"/>
            </geometry>
            <material name="">
                <color rgba="0.8 0.2 0.2 1"/>
            </material>
        </visual>
        <collision name="base_collision">
            <geometry>
                <box size="${base_size_x} ${base_size_y} ${base_size_z}"/>
            </geometry>
        </collision>
    </link>

    <!-- Left Wheel -->
    <link name="left_wheel">
        <pose>-0.1 0.2 0 1.5708 0 0</pose>
        <inertial>
            <mass value="0.5"/>
            <inertia ixx="0.02" ixy="0" ixz="0" iyy="0.02" iyz="0" izz="0.02"/>
        </inertial>
        <visual name="left_wheel_visual">
            <geometry>
                <cylinder radius="${wheel_radius}" length="${wheel_width}"/>
            </geometry>
            <material name="">
                <color rgba="0.2 0.2 0.2 1"/>
            </material>
        </visual>
        <collision name="left_wheel_collision">
            <geometry>
                <cylinder radius="${wheel_radius}" length="${wheel_width}"/>
            </geometry>
        </collision>
    </link>

    <!-- Right Wheel -->
    <link name="right_wheel">
        <pose>-0.1 -0.2 0 1.5708 0 0</pose>
        <inertial>
            <mass value="0.5"/>
            <inertia ixx="0.02" ixy="0" ixz="0" iyy="0.02" iyz="0" izz="0.02"/>
        </inertial>
        <visual name="right_wheel_visual">
            <geometry>
                <cylinder radius="${wheel_radius}" length="${wheel_width}"/>
            </geometry>
            <material name="">
                <color rgba="0.2 0.2 0.2 1"/>
            </material>
        </visual>
        <collision name="right_wheel_collision">
            <geometry>
                <cylinder radius="${wheel_radius}" length="${wheel_width}"/>
            </geometry>
        </collision>
    </link>

    <!-- Caster Wheel -->
    <link name="caster_wheel">
        <pose>0.15 0 -0.1 0 0 0</pose>
        <inertial>
            <mass value="0.1"/>
            <inertia ixx="0.001" ixy="0" ixz="0" iyy="0.001" iyz="0" izz="0.001"/>
        </inertial>
        <visual name="caster_visual">
            <geometry>
                <sphere radius="${caster_radius}"/>
            </geometry>
            <material name="">
                <color rgba="0.5 0.5 0.5 1"/>
            </material>
        </visual>
        <collision name="caster_collision">
            <geometry>
                <sphere radius="${caster_radius}"/>
            </geometry>
        </collision>
    </link>

    <!-- Joints -->
    <joint name="left_wheel_joint" type="continuous">
        <parent link="base_link"/>
        <child link="left_wheel"/>
        <origin xyz="-0.1 0.2 0" rpy="1.5708 0 0"/>
        <axis xyz="0 0 1"/>
    </joint>

    <joint name="right_wheel_joint" type="continuous">
        <parent link="base_link"/>
        <child link="right_wheel"/>
        <origin xyz="-0.1 -0.2 0" rpy="1.5708 0 0"/>
        <axis xyz="0 0 1"/>
    </joint>

    <joint name="caster_wheel_joint" type="fixed">
        <parent link="base_link"/>
        <child link="caster_wheel"/>
        <origin xyz="0.15 0 -0.1" rpy="0 0 0"/>
    </joint>
</robot>
