<?xml version="1.0"?>
<robot xmlns:xacro="http://www.ros.org/wiki/xacro" name="com01"
  xmlns:math="http://www.w3.org/2005/xpath-functions/math">
  <xacro:property name="M_PI" value="3.1415926535897931" />
  <!-- Parameters -->
  <xacro:property name="base_mass" value="5.0" />
  <xacro:property name="wheel_mass" value="0.5" />
  <xacro:property name="caster_mass" value="0.1" />

  <xacro:property name="base_size" value="0.4 0.3 0.2" />
  <xacro:property name="wheel_radius" value="0.15" />
  <xacro:property name="wheel_width" value="0.05" />
  <xacro:property name="caster_radius" value="0.05" />

  <xacro:property name="wheel_separation" value="0.4" />
  <xacro:property name="wheel_y_offset" value="0.2" />
  <xacro:property name="wheel_x_offset" value="-0.1" />
  <xacro:property name="caster_x_offset" value="0.15" />
  <xacro:property name="caster_z_offset" value="-0.1" />

  <!-- Base Link -->
  <link name="base_link">
    <inertial>
      <mass value="${base_mass}" />
      <inertia ixx="0.1" ixy="0.0" ixz="0.0" iyy="0.1" iyz="0.0" izz="0.1" />
    </inertial>

    <visual>
      <geometry>
        <box size="${base_size}" />
      </geometry>
      <material name="red">
        <color rgba="0.8 0.2 0.2 1" />
      </material>
    </visual>

    <collision>
      <geometry>
        <box size="${base_size}" />
      </geometry>
    </collision>
  </link>

  <!-- Left Wheel -->
  <xacro:macro name="wheel" params="prefix reflect">
    <link name="${prefix}_wheel">
      <inertial>
        <mass value="${wheel_mass}" />
        <inertia ixx="0.02" ixy="0.0" ixz="0.0" iyy="0.02" iyz="0.0" izz="0.02" />
      </inertial>

      <visual>
        <origin xyz="0 0 0" rpy="${M_PI/2} 0 0" />
        <geometry>
          <cylinder radius="${wheel_radius}" length="${wheel_width}" />
        </geometry>
        <material name="black">
          <color rgba="0.1 0.1 0.1 1" />
        </material>
      </visual>

      <collision>
        <origin xyz="0 0 0" rpy="${M_PI/2} 0 0" />
        <geometry>
          <cylinder radius="${wheel_radius}" length="${wheel_width}" />
        </geometry>
      </collision>
    </link>

    <joint name="${prefix}_wheel_joint" type="continuous">
      <parent link="base_link" />
      <child link="${prefix}_wheel" />
      <origin xyz="${wheel_x_offset} ${reflect * wheel_y_offset} 0" rpy="0 0 0" />
      <axis xyz="0 1 0" />
    </joint>

    <gazebo reference="${prefix}_wheel">
      <mu1 value="1.0" />
      <mu2 value="1.0" />
      <kp value="10000000.0" />
      <kd value="1.0" />
    </gazebo>
  </xacro:macro>

  <!-- Create left and right wheels -->
  <xacro:wheel prefix="left" reflect="1" />
  <xacro:wheel prefix="right" reflect="-1" />

  <!-- Caster Wheel -->
  <link name="caster_wheel">
    <inertial>
      <mass value="${caster_mass}" />
      <inertia ixx="0.001" ixy="0.0" ixz="0.0" iyy="0.001" iyz="0.0" izz="0.001" />
    </inertial>

    <visual>
      <geometry>
        <sphere radius="${caster_radius}" />
      </geometry>
      <material name="gray">
        <color rgba="0.5 0.5 0.5 1" />
      </material>
    </visual>

    <collision>
      <geometry>
        <sphere radius="${caster_radius}" />
      </geometry>
    </collision>
  </link>

  <joint name="caster_wheel_joint" type="fixed">
    <parent link="base_link" />
    <child link="caster_wheel" />
    <origin xyz="${caster_x_offset} 0 ${caster_z_offset}" rpy="0 0 0" />
  </joint>

  <!-- IMU Link -->
  <link name="imu_link">
    <inertial>
      <mass value="0.01" />
      <inertia ixx="0.001" ixy="0.0" ixz="0.0" iyy="0.001" iyz="0.0" izz="0.001" />
    </inertial>

    <visual>
      <geometry>
        <box size="0.1 0.1 0.05" />
      </geometry>
      <material name="blue">
        <color rgba="0.5 0.5 1 1" />
      </material>
    </visual>

    <collision>
      <geometry>
        <box size="0.1 0.1 0.05" />
      </geometry>
    </collision>
  </link>
  <joint name="imu_joint" type="fixed">
    <parent link="base_link" />
    <child link="imu_link" />
    <origin xyz="0 0 0.2" rpy="0 0 0" />
  </joint>
  <gazebo reference="imu_link">
    <sensor name="imu_sensor" type="imu">
      <always_on>1</always_on>
      <update_rate>10</update_rate>
      <visualize>true</visualize>
      <topic>imu</topic>
    </sensor>
  </gazebo>

  <!-- Lidar Link -->
  <link name="lidar_link">
    <inertial>
      <mass value="0.01" />
      <inertia ixx="0.001" ixy="0.0" ixz="0.0" iyy="0.001" iyz="0.0" izz="0.001" />
    </inertial>

    <visual>
      <geometry>
        <box size="0.1 0.1 0.05" />
      </geometry>
      <material name="green">
        <color rgba="0.5 1 0.5 1" />
      </material>
    </visual>

    <collision>
      <geometry>
        <box size="0.1 0.1 0.05" />
      </geometry>
    </collision>
  </link>
  <joint name="lidar_joint" type="fixed">
    <parent link="base_link" />
    <child link="lidar_link" />
    <origin xyz="0 0 0.15" rpy="0 0 0" />
  </joint>
  <gazebo reference="lidar_link">
    <sensor name='gpu_lidar' type='gpu_lidar'>
      <topic>scan</topic>
      <update_rate>10</update_rate>
      <ray>
        <scan>
          <horizontal>
            <samples>640</samples>
            <resolution>1</resolution>
            <min_angle>-1.396263</min_angle>
            <max_angle>1.396263</max_angle>
          </horizontal>
          <vertical>
            <samples>1</samples>
            <resolution>0.01</resolution>
            <min_angle>0</min_angle>
            <max_angle>0</max_angle>
          </vertical>
        </scan>
        <range>
          <min>0.08</min>
          <max>10.0</max>
          <resolution>0.01</resolution>
        </range>
      </ray>
      <always_on>1</always_on>
      <visualize>true</visualize>
    </sensor>
  </gazebo>

  <!-- Gazebo Plugins -->
  <gazebo>
    <plugin filename="gz-sim-diff-drive-system" name="gz::sim::systems::DiffDrive">
      <left_joint>left_wheel_joint</left_joint>
      <right_joint>right_wheel_joint</right_joint>
      <wheel_separation>${wheel_separation}</wheel_separation>
      <wheel_radius>${wheel_radius}</wheel_radius>
      <topic>cmd_vel</topic>
      <odom_topic>odom</odom_topic>
      <frame_id>odom</frame_id>
      <child_frame_id>base_link</child_frame_id>
      <odom_publish_frequency>30</odom_publish_frequency>
      <publish_odom_tf>false</publish_odom_tf>
    </plugin>
  </gazebo>

  <gazebo>
    <plugin filename="gz-sim-joint-state-publisher-system" name="gz::sim::systems::JointStatePublisher">
    </plugin>
  </gazebo>

</robot>
